2021-02-13 20:01:03,966 ERROR: Exception on /favicon.ico [GET] [in /home/ubuntu/app_flask/My_flask_blog/venv/lib/python3.8/site-packages/flask/app.py:1891]
Traceback (most recent call last):
  File "/home/ubuntu/app_flask/My_flask_blog/venv/lib/python3.8/site-packages/flask/app.py", line 2447, in wsgi_app
    response = self.full_dispatch_request()
  File "/home/ubuntu/app_flask/My_flask_blog/venv/lib/python3.8/site-packages/flask/app.py", line 1952, in full_dispatch_request
    rv = self.handle_user_exception(e)
  File "/home/ubuntu/app_flask/My_flask_blog/venv/lib/python3.8/site-packages/flask/app.py", line 1821, in handle_user_exception
    reraise(exc_type, exc_value, tb)
  File "/home/ubuntu/app_flask/My_flask_blog/venv/lib/python3.8/site-packages/flask/_compat.py", line 39, in reraise
    raise value
  File "/home/ubuntu/app_flask/My_flask_blog/venv/lib/python3.8/site-packages/flask/app.py", line 1950, in full_dispatch_request
    rv = self.dispatch_request()
  File "/home/ubuntu/app_flask/My_flask_blog/venv/lib/python3.8/site-packages/flask/app.py", line 1936, in dispatch_request
    return self.view_functions[rule.endpoint](**req.view_args)
  File "/home/ubuntu/app_flask/My_flask_blog/app/main/routes.py", line 190, in favicon
    return send_from_directory(os.path.join(bp.root_path, 'static', 'images'),
NameError: name 'send_from_directory' is not defined
2021-02-13 20:02:25,676 ERROR: Exception on /favicon.ico [GET] [in /home/ubuntu/app_flask/My_flask_blog/venv/lib/python3.8/site-packages/flask/app.py:1891]
Traceback (most recent call last):
  File "/home/ubuntu/app_flask/My_flask_blog/venv/lib/python3.8/site-packages/flask/app.py", line 2447, in wsgi_app
    response = self.full_dispatch_request()
  File "/home/ubuntu/app_flask/My_flask_blog/venv/lib/python3.8/site-packages/flask/app.py", line 1952, in full_dispatch_request
    rv = self.handle_user_exception(e)
  File "/home/ubuntu/app_flask/My_flask_blog/venv/lib/python3.8/site-packages/flask/app.py", line 1821, in handle_user_exception
    reraise(exc_type, exc_value, tb)
  File "/home/ubuntu/app_flask/My_flask_blog/venv/lib/python3.8/site-packages/flask/_compat.py", line 39, in reraise
    raise value
  File "/home/ubuntu/app_flask/My_flask_blog/venv/lib/python3.8/site-packages/flask/app.py", line 1950, in full_dispatch_request
    rv = self.dispatch_request()
  File "/home/ubuntu/app_flask/My_flask_blog/venv/lib/python3.8/site-packages/flask/app.py", line 1936, in dispatch_request
    return self.view_functions[rule.endpoint](**req.view_args)
  File "/home/ubuntu/app_flask/My_flask_blog/app/main/routes.py", line 190, in favicon
    return send_from_directory(os.path.join(bp.root_path, 'static', 'images'),
NameError: name 'send_from_directory' is not defined
2021-02-13 20:02:39,338 ERROR: Exception on /favicon.ico [GET] [in /home/ubuntu/app_flask/My_flask_blog/venv/lib/python3.8/site-packages/flask/app.py:1891]
Traceback (most recent call last):
  File "/home/ubuntu/app_flask/My_flask_blog/venv/lib/python3.8/site-packages/flask/app.py", line 2447, in wsgi_app
    response = self.full_dispatch_request()
  File "/home/ubuntu/app_flask/My_flask_blog/venv/lib/python3.8/site-packages/flask/app.py", line 1952, in full_dispatch_request
    rv = self.handle_user_exception(e)
  File "/home/ubuntu/app_flask/My_flask_blog/venv/lib/python3.8/site-packages/flask/app.py", line 1821, in handle_user_exception
    reraise(exc_type, exc_value, tb)
  File "/home/ubuntu/app_flask/My_flask_blog/venv/lib/python3.8/site-packages/flask/_compat.py", line 39, in reraise
    raise value
  File "/home/ubuntu/app_flask/My_flask_blog/venv/lib/python3.8/site-packages/flask/app.py", line 1950, in full_dispatch_request
    rv = self.dispatch_request()
  File "/home/ubuntu/app_flask/My_flask_blog/venv/lib/python3.8/site-packages/flask/app.py", line 1936, in dispatch_request
    return self.view_functions[rule.endpoint](**req.view_args)
  File "/home/ubuntu/app_flask/My_flask_blog/app/main/routes.py", line 190, in favicon
    return send_from_directory(os.path.join(bp.root_path, 'static', 'images'),
NameError: name 'send_from_directory' is not defined
2021-02-13 20:03:04,339 ERROR: Exception on /favicon.ico [GET] [in /home/ubuntu/app_flask/My_flask_blog/venv/lib/python3.8/site-packages/flask/app.py:1891]
Traceback (most recent call last):
  File "/home/ubuntu/app_flask/My_flask_blog/venv/lib/python3.8/site-packages/flask/app.py", line 2447, in wsgi_app
    response = self.full_dispatch_request()
  File "/home/ubuntu/app_flask/My_flask_blog/venv/lib/python3.8/site-packages/flask/app.py", line 1952, in full_dispatch_request
    rv = self.handle_user_exception(e)
  File "/home/ubuntu/app_flask/My_flask_blog/venv/lib/python3.8/site-packages/flask/app.py", line 1821, in handle_user_exception
    reraise(exc_type, exc_value, tb)
  File "/home/ubuntu/app_flask/My_flask_blog/venv/lib/python3.8/site-packages/flask/_compat.py", line 39, in reraise
    raise value
  File "/home/ubuntu/app_flask/My_flask_blog/venv/lib/python3.8/site-packages/flask/app.py", line 1950, in full_dispatch_request
    rv = self.dispatch_request()
  File "/home/ubuntu/app_flask/My_flask_blog/venv/lib/python3.8/site-packages/flask/app.py", line 1936, in dispatch_request
    return self.view_functions[rule.endpoint](**req.view_args)
  File "/home/ubuntu/app_flask/My_flask_blog/app/main/routes.py", line 190, in favicon
    return send_from_directory(os.path.join(bp.root_path, 'static', 'images'),
NameError: name 'send_from_directory' is not defined
2021-02-13 20:03:54,507 ERROR: Exception on /favicon.ico [GET] [in /home/ubuntu/app_flask/My_flask_blog/venv/lib/python3.8/site-packages/flask/app.py:1891]
Traceback (most recent call last):
  File "/home/ubuntu/app_flask/My_flask_blog/venv/lib/python3.8/site-packages/flask/app.py", line 2447, in wsgi_app
    response = self.full_dispatch_request()
  File "/home/ubuntu/app_flask/My_flask_blog/venv/lib/python3.8/site-packages/flask/app.py", line 1952, in full_dispatch_request
    rv = self.handle_user_exception(e)
  File "/home/ubuntu/app_flask/My_flask_blog/venv/lib/python3.8/site-packages/flask/app.py", line 1821, in handle_user_exception
    reraise(exc_type, exc_value, tb)
  File "/home/ubuntu/app_flask/My_flask_blog/venv/lib/python3.8/site-packages/flask/_compat.py", line 39, in reraise
    raise value
  File "/home/ubuntu/app_flask/My_flask_blog/venv/lib/python3.8/site-packages/flask/app.py", line 1950, in full_dispatch_request
    rv = self.dispatch_request()
  File "/home/ubuntu/app_flask/My_flask_blog/venv/lib/python3.8/site-packages/flask/app.py", line 1936, in dispatch_request
    return self.view_functions[rule.endpoint](**req.view_args)
  File "/home/ubuntu/app_flask/My_flask_blog/app/main/routes.py", line 190, in favicon
    return send_from_directory(os.path.join(bp.root_path, 'static', 'images'),
NameError: name 'send_from_directory' is not defined
