2021-02-13 20:22:06,733 ERROR: Exception on /auth/login [POST] [in /home/ubuntu/app_flask/My_flask_blog/venv/lib/python3.8/site-packages/flask/app.py:1891]
Traceback (most recent call last):
  File "/home/ubuntu/app_flask/My_flask_blog/venv/lib/python3.8/site-packages/sqlalchemy/engine/base.py", line 1276, in _execute_context
    self.dialect.do_execute(
  File "/home/ubuntu/app_flask/My_flask_blog/venv/lib/python3.8/site-packages/sqlalchemy/engine/default.py", line 609, in do_execute
    cursor.execute(statement, parameters)
  File "/home/ubuntu/app_flask/My_flask_blog/venv/lib/python3.8/site-packages/pymysql/cursors.py", line 148, in execute
    result = self._query(query)
  File "/home/ubuntu/app_flask/My_flask_blog/venv/lib/python3.8/site-packages/pymysql/cursors.py", line 310, in _query
    conn.query(q)
  File "/home/ubuntu/app_flask/My_flask_blog/venv/lib/python3.8/site-packages/pymysql/connections.py", line 548, in query
    self._affected_rows = self._read_query_result(unbuffered=unbuffered)
  File "/home/ubuntu/app_flask/My_flask_blog/venv/lib/python3.8/site-packages/pymysql/connections.py", line 775, in _read_query_result
    result.read()
  File "/home/ubuntu/app_flask/My_flask_blog/venv/lib/python3.8/site-packages/pymysql/connections.py", line 1156, in read
    first_packet = self.connection._read_packet()
  File "/home/ubuntu/app_flask/My_flask_blog/venv/lib/python3.8/site-packages/pymysql/connections.py", line 725, in _read_packet
    packet.raise_for_error()
  File "/home/ubuntu/app_flask/My_flask_blog/venv/lib/python3.8/site-packages/pymysql/protocol.py", line 221, in raise_for_error
    err.raise_mysql_exception(self._data)
  File "/home/ubuntu/app_flask/My_flask_blog/venv/lib/python3.8/site-packages/pymysql/err.py", line 143, in raise_mysql_exception
    raise errorclass(errno, errval)
pymysql.err.OperationalError: (1054, "Unknown column 'user.last_message_read_time' in 'field list'")

The above exception was the direct cause of the following exception:

Traceback (most recent call last):
  File "/home/ubuntu/app_flask/My_flask_blog/venv/lib/python3.8/site-packages/flask/app.py", line 2447, in wsgi_app
    response = self.full_dispatch_request()
  File "/home/ubuntu/app_flask/My_flask_blog/venv/lib/python3.8/site-packages/flask/app.py", line 1952, in full_dispatch_request
    rv = self.handle_user_exception(e)
  File "/home/ubuntu/app_flask/My_flask_blog/venv/lib/python3.8/site-packages/flask/app.py", line 1821, in handle_user_exception
    reraise(exc_type, exc_value, tb)
  File "/home/ubuntu/app_flask/My_flask_blog/venv/lib/python3.8/site-packages/flask/_compat.py", line 39, in reraise
    raise value
  File "/home/ubuntu/app_flask/My_flask_blog/venv/lib/python3.8/site-packages/flask/app.py", line 1950, in full_dispatch_request
    rv = self.dispatch_request()
  File "/home/ubuntu/app_flask/My_flask_blog/venv/lib/python3.8/site-packages/flask/app.py", line 1936, in dispatch_request
    return self.view_functions[rule.endpoint](**req.view_args)
  File "/home/ubuntu/app_flask/My_flask_blog/app/auth/routes.py", line 19, in login
    user = User.query.filter_by(username=form.username.data).first()
  File "/home/ubuntu/app_flask/My_flask_blog/venv/lib/python3.8/site-packages/sqlalchemy/orm/query.py", line 3429, in first
    ret = list(self[0:1])
  File "/home/ubuntu/app_flask/My_flask_blog/venv/lib/python3.8/site-packages/sqlalchemy/orm/query.py", line 3203, in __getitem__
    return list(res)
  File "/home/ubuntu/app_flask/My_flask_blog/venv/lib/python3.8/site-packages/sqlalchemy/orm/query.py", line 3535, in __iter__
    return self._execute_and_instances(context)
  File "/home/ubuntu/app_flask/My_flask_blog/venv/lib/python3.8/site-packages/sqlalchemy/orm/query.py", line 3560, in _execute_and_instances
    result = conn.execute(querycontext.statement, self._params)
  File "/home/ubuntu/app_flask/My_flask_blog/venv/lib/python3.8/site-packages/sqlalchemy/engine/base.py", line 1011, in execute
    return meth(self, multiparams, params)
  File "/home/ubuntu/app_flask/My_flask_blog/venv/lib/python3.8/site-packages/sqlalchemy/sql/elements.py", line 298, in _execute_on_connection
    return connection._execute_clauseelement(self, multiparams, params)
  File "/home/ubuntu/app_flask/My_flask_blog/venv/lib/python3.8/site-packages/sqlalchemy/engine/base.py", line 1124, in _execute_clauseelement
    ret = self._execute_context(
  File "/home/ubuntu/app_flask/My_flask_blog/venv/lib/python3.8/site-packages/sqlalchemy/engine/base.py", line 1316, in _execute_context
    self._handle_dbapi_exception(
  File "/home/ubuntu/app_flask/My_flask_blog/venv/lib/python3.8/site-packages/sqlalchemy/engine/base.py", line 1510, in _handle_dbapi_exception
    util.raise_(
  File "/home/ubuntu/app_flask/My_flask_blog/venv/lib/python3.8/site-packages/sqlalchemy/util/compat.py", line 182, in raise_
    raise exception
  File "/home/ubuntu/app_flask/My_flask_blog/venv/lib/python3.8/site-packages/sqlalchemy/engine/base.py", line 1276, in _execute_context
    self.dialect.do_execute(
  File "/home/ubuntu/app_flask/My_flask_blog/venv/lib/python3.8/site-packages/sqlalchemy/engine/default.py", line 609, in do_execute
    cursor.execute(statement, parameters)
  File "/home/ubuntu/app_flask/My_flask_blog/venv/lib/python3.8/site-packages/pymysql/cursors.py", line 148, in execute
    result = self._query(query)
  File "/home/ubuntu/app_flask/My_flask_blog/venv/lib/python3.8/site-packages/pymysql/cursors.py", line 310, in _query
    conn.query(q)
  File "/home/ubuntu/app_flask/My_flask_blog/venv/lib/python3.8/site-packages/pymysql/connections.py", line 548, in query
    self._affected_rows = self._read_query_result(unbuffered=unbuffered)
  File "/home/ubuntu/app_flask/My_flask_blog/venv/lib/python3.8/site-packages/pymysql/connections.py", line 775, in _read_query_result
    result.read()
  File "/home/ubuntu/app_flask/My_flask_blog/venv/lib/python3.8/site-packages/pymysql/connections.py", line 1156, in read
    first_packet = self.connection._read_packet()
  File "/home/ubuntu/app_flask/My_flask_blog/venv/lib/python3.8/site-packages/pymysql/connections.py", line 725, in _read_packet
    packet.raise_for_error()
  File "/home/ubuntu/app_flask/My_flask_blog/venv/lib/python3.8/site-packages/pymysql/protocol.py", line 221, in raise_for_error
    err.raise_mysql_exception(self._data)
  File "/home/ubuntu/app_flask/My_flask_blog/venv/lib/python3.8/site-packages/pymysql/err.py", line 143, in raise_mysql_exception
    raise errorclass(errno, errval)
sqlalchemy.exc.OperationalError: (pymysql.err.OperationalError) (1054, "Unknown column 'user.last_message_read_time' in 'field list'")
[SQL: SELECT user.id AS user_id, user.username AS user_username, user.email AS user_email, user.password_hash AS user_password_hash, user.about_me AS user_about_me, user.last_seen AS user_last_seen, user.last_message_read_time AS user_last_message_read_time 
FROM user 
WHERE user.username = %(username_1)s 
 LIMIT %(param_1)s]
[parameters: {'username_1': 'Admin', 'param_1': 1}]
(Background on this error at: http://sqlalche.me/e/13/e3q8)
